[20/09/2021 20:12] INFO: Lancement du bot
[20/09/2021 20:12] ERROR: 
Failed to load extension plugins.rss.bot.main
Traceback (most recent call last):
  File "c:\Users\vince\Documents\Projets\Gunibot.py\venv\lib\site-packages\discord\ext\commands\bot.py", line 618, in _load_from_module_spec
    setup(self)
  File "C:\Users\vince\Documents\Projets\Gunibot.py\plugins\rss\bot\main.py", line 1429, in setup
    bot.add_cog(Rss(bot))
  File "C:\Users\vince\Documents\Projets\Gunibot.py\plugins\rss\bot\main.py", line 37, in __init__
    self.twitterAPI = twitter.Api(**bot.config['twitter'], tweet_mode="extended")
KeyError: 'twitter'

The above exception was the direct cause of the following exception:

Traceback (most recent call last):
  File "start.py", line 92, in main
    client.load_extension(extension)
  File "c:\Users\vince\Documents\Projets\Gunibot.py\venv\lib\site-packages\discord\ext\commands\bot.py", line 678, in load_extension
    self._load_from_module_spec(spec, name)
  File "c:\Users\vince\Documents\Projets\Gunibot.py\venv\lib\site-packages\discord\ext\commands\bot.py", line 623, in _load_from_module_spec
    raise errors.ExtensionFailed(key, e) from e
discord.ext.commands.errors.ExtensionFailed: Extension 'plugins.rss.bot.main' raised an error: KeyError: 'twitter'
[20/09/2021 20:15] INFO: Lancement du bot
[20/09/2021 20:15] ERROR: 
Failed to load extension plugins.rss.bot.main
Traceback (most recent call last):
  File "c:\Users\vince\Documents\Projets\Gunibot.py\venv\lib\site-packages\discord\ext\commands\bot.py", line 618, in _load_from_module_spec
    setup(self)
  File "C:\Users\vince\Documents\Projets\Gunibot.py\plugins\rss\bot\main.py", line 1429, in setup
    bot.add_cog(Rss(bot))
  File "C:\Users\vince\Documents\Projets\Gunibot.py\plugins\rss\bot\main.py", line 37, in __init__
    self.twitterAPI = twitter.Api(**bot.config['twitter'], tweet_mode="extended")
KeyError: 'twitter'

The above exception was the direct cause of the following exception:

Traceback (most recent call last):
  File "start.py", line 92, in main
    client.load_extension(extension)
  File "c:\Users\vince\Documents\Projets\Gunibot.py\venv\lib\site-packages\discord\ext\commands\bot.py", line 678, in load_extension
    self._load_from_module_spec(spec, name)
  File "c:\Users\vince\Documents\Projets\Gunibot.py\venv\lib\site-packages\discord\ext\commands\bot.py", line 623, in _load_from_module_spec
    raise errors.ExtensionFailed(key, e) from e
discord.ext.commands.errors.ExtensionFailed: Extension 'plugins.rss.bot.main' raised an error: KeyError: 'twitter'
[20/09/2021 20:17] INFO: Lancement du bot
[20/09/2021 20:17] DEBUG: Pas d'arguments trouvés!
[20/09/2021 20:17] DEBUG: [hypesquad] Started roles check
[20/09/2021 20:17] INFO: [hypesquad] Finished roles check in 0.0s with 0 editions
[20/09/2021 20:17] INFO:  Boucle rss commencée !
[20/09/2021 20:17] INFO: Check RSS lancé
[20/09/2021 20:17] DEBUG: **RSS loop done** in 0.001s (0/0 flows)
[20/09/2021 20:17] INFO:  Boucle rss terminée en 0.0s!
[20/09/2021 21:03] INFO: Lancement du bot
[20/09/2021 21:03] ERROR: 
Failed to load extension plugins.contact.bot.main
Traceback (most recent call last):
  File "c:\Users\vince\Documents\Projets\Gunibot.py\venv\lib\site-packages\discord\ext\commands\bot.py", line 606, in _load_from_module_spec
    spec.loader.exec_module(lib)
  File "<frozen importlib._bootstrap_external>", line 850, in exec_module
  File "<frozen importlib._bootstrap>", line 228, in _call_with_frames_removed
  File "C:\Users\vince\Documents\Projets\Gunibot.py\plugins\contact\bot\main.py", line 14, in <module>
    class Contact(commands.Cog):
  File "C:\Users\vince\Documents\Projets\Gunibot.py\plugins\contact\bot\main.py", line 31, in Contact
    async def config_contact_channel(self, ctx: MyContext, *, channel: discord.TextChannel):
NameError: name 'MyContext' is not defined

The above exception was the direct cause of the following exception:

Traceback (most recent call last):
  File "start.py", line 94, in main
    client.load_extension(extension)
  File "c:\Users\vince\Documents\Projets\Gunibot.py\venv\lib\site-packages\discord\ext\commands\bot.py", line 678, in load_extension
    self._load_from_module_spec(spec, name)
  File "c:\Users\vince\Documents\Projets\Gunibot.py\venv\lib\site-packages\discord\ext\commands\bot.py", line 609, in _load_from_module_spec
    raise errors.ExtensionFailed(key, e) from e
discord.ext.commands.errors.ExtensionFailed: Extension 'plugins.contact.bot.main' raised an error: NameError: name 'MyContext' is not defined
[20/09/2021 21:04] INFO: Lancement du bot
[20/09/2021 21:04] ERROR: 
Failed to load extension plugins.contact.bot.main
Traceback (most recent call last):
  File "c:\Users\vince\Documents\Projets\Gunibot.py\venv\lib\site-packages\discord\ext\commands\bot.py", line 618, in _load_from_module_spec
    setup(self)
  File "C:\Users\vince\Documents\Projets\Gunibot.py\plugins\contact\bot\main.py", line 159, in setup
    bot.add_cog(Contact(bot))
  File "C:\Users\vince\Documents\Projets\Gunibot.py\plugins\contact\bot\main.py", line 22, in __init__
    bot.get_command("config").add_command(self.config_contact_channel)
AttributeError: 'NoneType' object has no attribute 'add_command'

The above exception was the direct cause of the following exception:

Traceback (most recent call last):
  File "start.py", line 94, in main
    client.load_extension(extension)
  File "c:\Users\vince\Documents\Projets\Gunibot.py\venv\lib\site-packages\discord\ext\commands\bot.py", line 678, in load_extension
    self._load_from_module_spec(spec, name)
  File "c:\Users\vince\Documents\Projets\Gunibot.py\venv\lib\site-packages\discord\ext\commands\bot.py", line 623, in _load_from_module_spec
    raise errors.ExtensionFailed(key, e) from e
discord.ext.commands.errors.ExtensionFailed: Extension 'plugins.contact.bot.main' raised an error: AttributeError: 'NoneType' object has no attribute 'add_command'
[20/09/2021 21:05] INFO: Lancement du bot
[20/09/2021 21:05] ERROR: 
Failed to load extension plugins.contact.bot.main
Traceback (most recent call last):
  File "c:\Users\vince\Documents\Projets\Gunibot.py\venv\lib\site-packages\discord\ext\commands\bot.py", line 618, in _load_from_module_spec
    setup(self)
  File "C:\Users\vince\Documents\Projets\Gunibot.py\plugins\contact\bot\main.py", line 159, in setup
    bot.add_cog(Contact(bot))
  File "C:\Users\vince\Documents\Projets\Gunibot.py\plugins\contact\bot\main.py", line 22, in __init__
    bot.get_command("config").add_command(self.config_contact_channel)
  File "c:\Users\vince\Documents\Projets\Gunibot.py\venv\lib\site-packages\discord\ext\commands\core.py", line 1143, in add_command
    raise TypeError('The command passed must be a subclass of Command')
TypeError: The command passed must be a subclass of Command

The above exception was the direct cause of the following exception:

Traceback (most recent call last):
  File "start.py", line 94, in main
    client.load_extension(extension)
  File "c:\Users\vince\Documents\Projets\Gunibot.py\venv\lib\site-packages\discord\ext\commands\bot.py", line 678, in load_extension
    self._load_from_module_spec(spec, name)
  File "c:\Users\vince\Documents\Projets\Gunibot.py\venv\lib\site-packages\discord\ext\commands\bot.py", line 623, in _load_from_module_spec
    raise errors.ExtensionFailed(key, e) from e
discord.ext.commands.errors.ExtensionFailed: Extension 'plugins.contact.bot.main' raised an error: TypeError: The command passed must be a subclass of Command
